2022-02-19 22:27:20,069 INFO: Microblog startup [in C:\Users\Jorge\Desktop\testblogg\microblog-main\app\__init__.py:89]
2022-02-19 22:31:16,383 INFO: Microblog startup [in C:\Users\Jorge\Desktop\testblogg\microblog-main\app\__init__.py:89]
2022-02-19 22:44:33,684 INFO: Microblog startup [in C:\Users\Jorge\Desktop\testblogg\microblog-main\app\__init__.py:89]
2022-02-20 00:15:53,141 INFO: Microblog startup [in C:\Users\Jorge\Desktop\testblogg\microblog-main\app\__init__.py:89]
2022-02-20 01:46:57,017 ERROR: Exception on /notifications [GET] [in c:\users\jorge\desktop\classes\venv\lib\site-packages\flask\app.py:1457]
Traceback (most recent call last):
  File "c:\users\jorge\desktop\classes\venv\lib\site-packages\sqlalchemy\engine\base.py", line 1802, in _execute_context
    self.dialect.do_execute(
  File "c:\users\jorge\desktop\classes\venv\lib\site-packages\sqlalchemy\engine\default.py", line 732, in do_execute
    cursor.execute(statement, parameters)
sqlite3.OperationalError: database is locked

The above exception was the direct cause of the following exception:

Traceback (most recent call last):
  File "c:\users\jorge\desktop\classes\venv\lib\site-packages\flask\app.py", line 2073, in wsgi_app
    response = self.full_dispatch_request()
  File "c:\users\jorge\desktop\classes\venv\lib\site-packages\flask\app.py", line 1518, in full_dispatch_request
    rv = self.handle_user_exception(e)
  File "c:\users\jorge\desktop\classes\venv\lib\site-packages\flask\app.py", line 1514, in full_dispatch_request
    rv = self.preprocess_request()
  File "c:\users\jorge\desktop\classes\venv\lib\site-packages\flask\app.py", line 1857, in preprocess_request
    rv = self.ensure_sync(before_func)()
  File "C:\Users\Jorge\Desktop\testblogg\microblog-main\app\main\routes.py", line 19, in before_request
    db.session.commit()
  File "<string>", line 2, in commit
  File "c:\users\jorge\desktop\classes\venv\lib\site-packages\sqlalchemy\orm\session.py", line 1431, in commit
    self._transaction.commit(_to_root=self.future)
  File "c:\users\jorge\desktop\classes\venv\lib\site-packages\sqlalchemy\orm\session.py", line 829, in commit
    self._prepare_impl()
  File "c:\users\jorge\desktop\classes\venv\lib\site-packages\sqlalchemy\orm\session.py", line 808, in _prepare_impl
    self.session.flush()
  File "c:\users\jorge\desktop\classes\venv\lib\site-packages\sqlalchemy\orm\session.py", line 3363, in flush
    self._flush(objects)
  File "c:\users\jorge\desktop\classes\venv\lib\site-packages\sqlalchemy\orm\session.py", line 3503, in _flush
    transaction.rollback(_capture_exception=True)
  File "c:\users\jorge\desktop\classes\venv\lib\site-packages\sqlalchemy\util\langhelpers.py", line 70, in __exit__
    compat.raise_(
  File "c:\users\jorge\desktop\classes\venv\lib\site-packages\sqlalchemy\util\compat.py", line 207, in raise_
    raise exception
  File "c:\users\jorge\desktop\classes\venv\lib\site-packages\sqlalchemy\orm\session.py", line 3463, in _flush
    flush_context.execute()
  File "c:\users\jorge\desktop\classes\venv\lib\site-packages\sqlalchemy\orm\unitofwork.py", line 456, in execute
    rec.execute(self)
  File "c:\users\jorge\desktop\classes\venv\lib\site-packages\sqlalchemy\orm\unitofwork.py", line 630, in execute
    util.preloaded.orm_persistence.save_obj(
  File "c:\users\jorge\desktop\classes\venv\lib\site-packages\sqlalchemy\orm\persistence.py", line 236, in save_obj
    _emit_update_statements(
  File "c:\users\jorge\desktop\classes\venv\lib\site-packages\sqlalchemy\orm\persistence.py", line 1000, in _emit_update_statements
    c = connection._execute_20(
  File "c:\users\jorge\desktop\classes\venv\lib\site-packages\sqlalchemy\engine\base.py", line 1614, in _execute_20
    return meth(self, args_10style, kwargs_10style, execution_options)
  File "c:\users\jorge\desktop\classes\venv\lib\site-packages\sqlalchemy\sql\elements.py", line 325, in _execute_on_connection
    return connection._execute_clauseelement(
  File "c:\users\jorge\desktop\classes\venv\lib\site-packages\sqlalchemy\engine\base.py", line 1481, in _execute_clauseelement
    ret = self._execute_context(
  File "c:\users\jorge\desktop\classes\venv\lib\site-packages\sqlalchemy\engine\base.py", line 1845, in _execute_context
    self._handle_dbapi_exception(
  File "c:\users\jorge\desktop\classes\venv\lib\site-packages\sqlalchemy\engine\base.py", line 2026, in _handle_dbapi_exception
    util.raise_(
  File "c:\users\jorge\desktop\classes\venv\lib\site-packages\sqlalchemy\util\compat.py", line 207, in raise_
    raise exception
  File "c:\users\jorge\desktop\classes\venv\lib\site-packages\sqlalchemy\engine\base.py", line 1802, in _execute_context
    self.dialect.do_execute(
  File "c:\users\jorge\desktop\classes\venv\lib\site-packages\sqlalchemy\engine\default.py", line 732, in do_execute
    cursor.execute(statement, parameters)
sqlalchemy.exc.OperationalError: (sqlite3.OperationalError) database is locked
[SQL: UPDATE user SET last_seen=? WHERE user.id = ?]
[parameters: ('2022-02-20 04:46:37.854547', 2)]
(Background on this error at: https://sqlalche.me/e/14/e3q8)
